Workbook
Name Slicer_City: #N/A
Name Slicer_Department: #N/A
Name Slicer_Designation: #N/A
Name Slicer_Education: #N/A
Name Slicer_Gender: #N/A
Name Slicer_office_location: #N/A
Name Slicer_Status: #N/A

Sheet HOME

Sheet DASHBOARD
H1: MORYA PVT. LTD
H3: HR DASHBOARD
A6: NO. OF DEPARTMENTS | D6: AVERAGE ATTENDANCE | G6: TOTAL PAYROLL | J6: NUMBER OF OFFICES | M6: AVERAGE SALARY | P6: NO. OF EMPLOYES | S6: ACTIVE EMPLOYEES
A7: 7 | D7: 0.9274 | G7: 44342958 | J7: 10 | M7: 88685.916 | P7: 500 | S7: 251
G9: EMP ID | H9: DEPARTMENT | I9: OFFICE | J9: DESIGNATION | L9: EMP TYPE | M9: SALARY | N9: RATING | O9: ATTENDACE % | P9: SHIFT | Q9: YEARS IN COMPANY | R9: STATUS | S9: LEAVES LEFT
G10: EMP012 | H10: =INDEX('MAIN DATA'!G5:G505,MATCH(G10,'MAIN DATA'!A5:A505,0)) -> Operations | I10: =INDEX('MAIN DATA'!H5:H505,MATCH(G10,'MAIN DATA'!A5:A505,0)) -> Delhi | J10: =INDEX('MAIN DATA'!I5:I505,MATCH(G10,'MAIN DATA'!A5:A505,0)) -> Operations Executive | L10: =INDEX('MAIN DATA'!K5:K505,MATCH(G10,'MAIN DATA'!A5:A505,0)) -> Contract | M10: =INDEX('MAIN DATA'!O5:O505,MATCH(G10,'MAIN DATA'!A5:A505,0)) -> 122526 | N10: =INDEX('MAIN DATA'!Q5:Q505,MATCH(G10,'MAIN DATA'!A5:A505,0)) -> 1 | O10: =INDEX('MAIN DATA'!R5:R505,MATCH(G10,'MAIN DATA'!A5:A505,0)) -> 89.2 | P10: =INDEX('MAIN DATA'!Z5:Z505,MATCH(G10,'MAIN DATA'!A5:A505,0)) -> Evening | Q10: =INDEX('MAIN DATA'!AA5:AA505,MATCH(G10,'MAIN DATA'!A5:A505,0)) -> 8.4 | R10: =INDEX('MAIN DATA'!L5:L505,MATCH(G10,'MAIN DATA'!A5:A505,0)) -> Active | S10: =INDEX('MAIN DATA'!S5:S505,MATCH(G10,'MAIN DATA'!A5:A505,0)) -> 4

Sheet KEY INSIGHTS

Sheet PIVOT TABLE
C1: I | F1: I | U1: I
A2: SUM OF SALARY AS PER DEPT. | C2: I | D2: AVG ATTENDANCE OF EMP | F2: I | G2: DISTRIBUTION OF EMP AS PER AGE AND DESIGNATION | U2: I
A3: Row Labels | B3: Sum of Salary | C3: I | D3: DESIGNATION | E3: AVG ATTENDANCE % | F3: I | G3: AGE OF | H3: DESIGNATION | U3: I
A4: Admin | B4: 5365533 | C4: I | D4: Accountant | E4: 93.869697 | F4: I | G4: EMPLOYEES | H4: Accountant | I4: Admin Officer | J4: Finance Analyst | K4: Marketing Executive | L4: Operations Executive | M4: Sales Executive | N4: Sales Manager | O4: Software Engineer | P4: System Admin | Q4: Grand Total | U4: I
A5: Finance | B5: 5612186 | C5: I | D5: Admin Officer | E5: 93.283051 | F5: I | G5: 21-30 | H5: 7 | I5: 11 | J5: 8 | K5: 16 | L5: 15 | M5: 15 | N5: 10 | O5: 12 | P5: 6 | Q5: 100 | U5: I
A6: IT | B6: 6549411 | C6: I | D6: Finance Analyst | E6: 91.807407 | F6: I | G6: 31-40 | H6: 6 | I6: 13 | J6: 3 | K6: 17 | L6: 23 | M6: 10 | N6: 10 | O6: 9 | P6: 13 | Q6: 104 | U6: I
A7: Marketing | B7: 6207823 | C7: I | D7: Marketing Executive | E7: 92.722222 | F7: I | G7: 41-50 | H7: 9 | I7: 18 | J7: 8 | K7: 17 | L7: 13 | M7: 9 | N7: 11 | O7: 8 | P7: 8 | Q7: 101 | U7: I
A8: Operations | B8: 6183420 | C8: I | D8: Operations Executive | E8: 92.486667 | F8: I | G8: 51-60 | H8: 11 | I8: 17 | J8: 8 | K8: 22 | L8: 24 | M8: 9 | N8: 8 | O8: 7 | P8: 10 | Q8: 116 | U8: I
A9: Sales | B9: 7431801 | C9: I | D9: Sales Executive | E9: 92.176744 | F9: I | G9: Grand Total | H9: 33 | I9: 59 | J9: 27 | K9: 72 | L9: 75 | M9: 43 | N9: 39 | O9: 36 | P9: 37 | Q9: 421 | U9: I
A10: Grand Total | B10: 37350174 | C10: I | D10: Sales Manager | E10: 92.994872 | F10: I | U10: I
C11: I | D11: Software Engineer | E11: 91.969444 | F11: I | U11: I
C12: I | D12: System Admin | E12: 93.227027 | F12: I | U12: I
C13: I | D13: Grand Total | E13: 92.739667 | F13: I | U13: I
C14: I | F14: I | G14: DISTRIBUTION OF DESIGNATION AS PER CITIES | U14: I
A15: AVERAGE SALARY | C15: I | F15: I | G15: * | H15: CITY | U15: I
A16: DESIGNATION | B16: AVG SALARY | C16: I | F16: I | G16: DESIGNATION | H16: Ahmedabad | I16: Bengaluru | J16: Chennai | K16: Delhi | L16: Hyderabad | M16: Jaipur | N16: Kochi | O16: Kolkata | P16: Mumbai | Q16: Pune | R16: Grand Total | U16: I
A17: Accountant | B17: 86124.485 | C17: I | F17: I | G17: Accountant | H17: 4 | I17: 2 | J17: 2 | K17: 3 | L17: 3 | M17: 2 | N17: 7 | O17: 3 | P17: 4 | Q17: 3 | R17: 33 | U17: I
A18: Admin Officer | B18: 90941.237 | C18: I | F18: I | G18: Admin Officer | H18: 3 | I18: 4 | J18: 6 | K18: 5 | L18: 5 | M18: 7 | N18: 1 | O18: 11 | P18: 9 | Q18: 8 | R18: 59 | U18: I
A19: Finance Analyst | B19: 102595.48 | C19: I | D19: TOP 5 EMP IN ATTENDANCE | F19: I | G19: Finance Analyst | H19: 4 | I19: 2 | J19: 1 | K19: 5 | L19: 1 | M19: 4 | N19: 2 | O19: 2 | P19: 3 | Q19: 3 | R19: 27 | U19: I
A20: Marketing Executive | B20: 86219.764 | C20: I | D20: EMP ID | E20: TOP 5 ATTENDANCE | F20: I | G20: Marketing Executive | H20: 6 | I20: 8 | J20: 10 | K20: 3 | L20: 6 | M20: 3 | N20: 10 | O20: 8 | P20: 10 | Q20: 8 | R20: 72 | U20: I
A21: Operations Executive | B21: 82445.6 | C21: I | D21: EMP109 | E21: 99.9 | F21: I | G21: Operations Executive | H21: 5 | I21: 8 | J21: 6 | K21: 9 | L21: 8 | M21: 5 | N21: 5 | O21: 9 | P21: 9 | Q21: 11 | R21: 75 | U21: I
A22: Sales Executive | B22: 85039.791 | C22: I | D22: EMP178 | E22: 99.9 | F22: I | G22: Sales Executive | H22: 3 | I22: 6 | J22: 5 | K22: 3 | L22: 6 | M22: 3 | N22: 5 | O22: 6 | P22: 4 | Q22: 2 | R22: 43 | U22: I
A23: Sales Manager | B23: 96797.179 | C23: I | D23: EMP179 | E23: 99.8 | F23: I | G23: Sales Manager | H23: 1 | I23: 6 | J23: 6 | K23: 4 | L23: 4 | M23: 3 | N23: 2 | O23: 3 | P23: 6 | Q23: 4 | R23: 39 | U23: I
A24: Software Engineer | B24: 86664.639 | C24: I | D24: EMP240 | E24: 99.8 | F24: I | G24: Software Engineer | H24: 3 | I24: 2 | K24: 6 | L24: 5 | M24: 3 | N24: 4 | O24: 3 | P24: 6 | Q24: 4 | R24: 36 | U24: I
A25: System Admin | B25: 92688.757 | C25: I | D25: EMP433 | E25: 99.8 | F25: I | G25: System Admin | H25: 2 | I25: 3 | J25: 2 | K25: 6 | L25: 2 | M25: 4 | N25: 4 | O25: 5 | P25: 6 | Q25: 3 | R25: 37 | U25: I
A26: Grand Total | B26: 88717.753 | C26: I | F26: I | G26: Grand Total | H26: 31 | I26: 41 | J26: 38 | K26: 44 | L26: 40 | M26: 34 | N26: 40 | O26: 50 | P26: 57 | Q26: 46 | R26: 421 | U26: I
C27: I | F27: I | U27: I
C28: I | F28: I | U28: I
C29: I | F29: I | U29: I
C30: I | D30: AVG ATTENDANCE PER DEPT. | F30: I | U30: I
C31: I | D31: Row Labels | E31: Average of Attendance % | F31: I | U31: I
A32: TOP 5 PAID EMPLOYEES | C32: I | D32: Admin | E32: 93.283051 | F32: I | U32: I
A33: Row Labels | B33: Sum of Salary | C33: I | D33: Finance | E33: 92.941667 | F33: I | G33: CITY WISE EMP COUNT | J33: SUM OF SALARY PER CITY | M33: CITYWISE AVG ATTENDANCE | P33: CITYWISE DESIGNATION COUNT | S33: AVG EXP PER CITY | U33: I
A34: EMP067 | B34: 149185 | C34: I | D34: IT | E34: 92.606849 | F34: I | G34: Row Labels | H34: Count of Employee ID | J34: Row Labels | K34: Sum of Salary | M34: Row Labels | N34: Average of Attendance % | P34: Row Labels | Q34: Count of Designation | S34: Row Labels | T34: Average of Experience (Years) | U34: I
A35: EMP266 | B35: 149734 | C35: I | D35: Marketing | E35: 92.722222 | F35: I | G35: Ahmedabad | H35: 31 | J35: Ahmedabad | K35: 2939811 | M35: Ahmedabad | N35: 92.677419 | P35: Ahmedabad | Q35: 31 | S35: Ahmedabad | T35: 10.129032 | U35: I
A36: EMP350 | B36: 149645 | C36: I | D36: Operations | E36: 92.486667 | F36: I | G36: Bengaluru | H36: 41 | J36: Bengaluru | K36: 3465697 | M36: Bengaluru | N36: 92.982927 | P36: Bengaluru | Q36: 41 | S36: Bengaluru | T36: 11.129268 | U36: I
A37: EMP398 | B37: 149517 | C37: I | D37: Sales | E37: 92.565854 | F37: I | G37: Chennai | H37: 38 | J37: Chennai | K37: 3132680 | M37: Chennai | N37: 92.394737 | P37: Chennai | Q37: 38 | S37: Chennai | T37: 9.9921053 | U37: I
A38: EMP470 | B38: 149740 | C38: I | D38: Grand Total | E38: 92.739667 | F38: I | G38: Delhi | H38: 44 | J38: Delhi | K38: 3965323 | M38: Delhi | N38: 92.856818 | P38: Delhi | Q38: 44 | S38: Delhi | T38: 10.245455 | U38: I
A39: Grand Total | B39: 747821 | C39: I | F39: I | G39: Hyderabad | H39: 40 | J39: Hyderabad | K39: 3572698 | M39: Hyderabad | N39: 92.2425 | P39: Hyderabad | Q39: 40 | S39: Hyderabad | T39: 10.19 | U39: I
C40: I | F40: I | G40: Jaipur | H40: 34 | J40: Jaipur | K40: 3040352 | M40: Jaipur | N40: 93.294118 | P40: Jaipur | Q40: 34 | S40: Jaipur | T40: 11.735294 | U40: I
...

Sheet MAIN DATA
A5: Employee ID | B5: First Name | C5: Last Name | D5: Gender | E5: DOB | F5: Age | G5: Department | H5: office location | I5: Designation | J5: Manager | K5: Employment Type | L5: Status | M5: Joining Date | N5: Experience (Years) | O5: Salary | P5: Bonus | Q5: Performance Rating | R5: Attendance % | S5: Leave Balance | T5: Email | U5: Phone | V5: City | W5: State | X5: Country | Y5: Education | Z5: Shift | AA5: YEARS IN COMPANY
A6: EMP001 | B6: Ananya | C6: Sharma | D6: Male | E6: 33293 | F6: 35 | G6: Sales | H6: Bengaluru | I6: Sales Manager | J6: Aarav Singh | K6: Full-Time | L6: On Leave | M6: 42805 | N6: 0.7 | O6: 137469 | P6: 7061 | Q6: 4 | R6: 91 | S6: 26 | T6: ananya.sharma1@company.com | U6: 9270345073 | V6: Bengaluru | W6: Karnataka | X6: India | Y6: MCA | Z6: Evening | AA6: =YEARFRAC(Table1[[#This Row],[Joining Date]],TODAY(),3) -> 9.4493151
A7: EMP002 | B7: Pooja | C7: Das | D7: Male | E7: 24930 | F7: 58 | G7: HR | H7: Kolkata | I7: HR Executive | J7: Sneha Kumar | K7: Full-Time | L7: Active | M7: 43376 | N7: 8.2 | O7: 116295 | P7: 34634 | Q7: 2 | R7: 85.6 | S7: 28 | T7: pooja.das2@company.com | U7: 9309046493 | V7: Kolkata | W7: West Bengal | X7: India | Y7: MBA | Z7: Evening | AA7: =YEARFRAC(Table1[[#This Row],[Joining Date]],TODAY(),3) -> 7.8849315
A8: EMP003 | B8: Meera | C8: Nair | D8: Female | E8: 33490 | F8: 34 | G8: IT | H8: Mumbai | I8: System Admin | J8: Kiran Gupta | K8: Full-Time | L8: Active | M8: 45703 | N8: 0.9 | O8: 38959 | P8: 14855 | Q8: 5 | R8: 99.6 | S8: 15 | T8: meera.nair3@company.com | U8: 9598743191 | V8: Mumbai | W8: Maharashtra | X8: India | Y8: B.Com | Z8: General | AA8: =YEARFRAC(Table1[[#This Row],[Joining Date]],TODAY(),3) -> 1.509589
A9: EMP004 | B9: Priya | C9: Joshi | D9: Male | E9: 36378 | F9: 26 | G9: HR | H9: Bengaluru | I9: HR Manager | J9: Priya Joshi | K9: Contract | L9: Active | M9: 43590 | N9: 17 | O9: 46188 | P9: 40981 | Q9: 3 | R9: 87.6 | S9: 8 | T9: priya.joshi4@company.com | U9: 9570640400 | V9: Bengaluru | W9: Karnataka | X9: India | Y9: MBA | Z9: General | AA9: =YEARFRAC(Table1[[#This Row],[Joining Date]],TODAY(),3) -> 7.2986301
A10: EMP005 | B10: Vikram | C10: Kumar | D10: Female | E10: 26039 | F10: 55 | G10: Sales | H10: Bengaluru | I10: Sales Manager | J10: Kiran Patel | K10: Contract | L10: Active | M10: 44701 | N10: 5.5 | O10: 132280 | P10: 33758 | Q10: 2 | R10: 85.1 | S10: 19 | T10: vikram.kumar5@company.com | U10: 9428481980 | V10: Bengaluru | W10: Karnataka | X10: India | Y10: MCA | Z10: Evening | AA10: =YEARFRAC(Table1[[#This Row],[Joining Date]],TODAY(),3) -> 4.2547945
A11: EMP006 | B11: Rohan | C11: Patel | D11: Female | E11: 32595 | F11: 37 | G11: Marketing | H11: Chennai | I11: Marketing Executive | J11: Ananya Sharma | K11: Contract | L11: On Leave | M11: 43674 | N11: 14.4 | O11: 124895 | P11: 32605 | Q11: 5 | R11: 88.2 | S11: 23 | T11: rohan.patel6@company.com | U11: 9197200220 | V11: Chennai | W11: Tamil Nadu | X11: India | Y11: B.Tech | Z11: Morning | AA11: =YEARFRAC(Table1[[#This Row],[Joining Date]],TODAY(),3) -> 7.0684932
A12: EMP007 | B12: Kiran | C12: Patel | D12: Female | E12: 34206 | F12: 32 | G12: HR | H12: Pune | I12: HR Manager | J12: Kiran Patel | K12: Full-Time | L12: On Leave | M12: 45788 | N12: 18.9 | O12: 136917 | P12: 39791 | Q12: 3 | R12: 95.3 | S12: 19 | T12: kiran.patel7@company.com | U12: 9983985334 | V12: Pune | W12: Maharashtra | X12: India | Y12: MBA | Z12: General | AA12: =YEARFRAC(Table1[[#This Row],[Joining Date]],TODAY(),3) -> 1.2767123
A13: EMP008 | B13: Priya | C13: Gupta | D13: Female | E13: 33276 | F13: 35 | G13: HR | H13: Kolkata | I13: HR Manager | J13: Aarav Joshi | K13: Contract | L13: On Leave | M13: 44387 | N13: 12.4 | O13: 65748 | P13: 24412 | Q13: 5 | R13: 98.2 | S13: 3 | T13: priya.gupta8@company.com | U13: 9254022888 | V13: Kolkata | W13: West Bengal | X13: India | Y13: BA | Z13: Evening | AA13: =YEARFRAC(Table1[[#This Row],[Joining Date]],TODAY(),3) -> 5.1150685
A14: EMP009 | B14: Priya | C14: Sharma | D14: Male | E14: 24681 | F14: 58 | G14: HR | H14: Mumbai | I14: HR Executive | J14: Pooja Rao | K14: Full-Time | L14: Active | M14: 44724 | N14: 9.4 | O14: 45308 | P14: 13314 | Q14: 4 | R14: 87.1 | S14: 27 | T14: priya.sharma9@company.com | U14: 9106673966 | V14: Mumbai | W14: Maharashtra | X14: India | Y14: MCA | Z14: General | AA14: =YEARFRAC(Table1[[#This Row],[Joining Date]],TODAY(),3) -> 4.1917808
A15: EMP010 | B15: Rahul | C15: Verma | D15: Male | E15: 28581 | F15: 48 | G15: HR | H15: Bengaluru | I15: HR Manager | J15: Pooja Kumar | K15: Full-Time | L15: On Leave | M15: 42821 | N15: 18.9 | O15: 80374 | P15: 6231 | Q15: 3 | R15: 99.9 | S15: 8 | T15: rahul.verma10@company.com | U15: 9250285888 | V15: Bengaluru | W15: Karnataka | X15: India | Y15: B.Tech | Z15: Morning | AA15: =YEARFRAC(Table1[[#This Row],[Joining Date]],TODAY(),3) -> 9.4054795
A16: EMP011 | B16: Meera | C16: Rao | D16: Female | E16: 34506 | F16: 32 | G16: Operations | H16: Jaipur | I16: Operations Executive | J16: Sneha Sharma | K16: Contract | L16: Active | M16: 45665 | N16: 19.9 | O16: 70206 | P16: 34366 | Q16: 4 | R16: 96.5 | S16: 0 | T16: meera.rao11@company.com | U16: 9530355595 | V16: Jaipur | W16: Rajasthan | X16: India | Y16: MCA | Z16: Morning | AA16: =YEARFRAC(Table1[[#This Row],[Joining Date]],TODAY(),3) -> 1.6136986
A17: EMP012 | B17: Aarav | C17: Rao | D17: Male | E17: 33627 | F17: 34 | G17: Operations | H17: Delhi | I17: Operations Executive | J17: Rohan Nair | K17: Contract | L17: Active | M17: 43188 | N17: 9.9 | O17: 122526 | P17: 18812 | Q17: 1 | R17: 89.2 | S17: 4 | T17: aarav.rao12@company.com | U17: 9946664484 | V17: Delhi | W17: Delhi | X17: India | Y17: MBA | Z17: Evening | AA17: =YEARFRAC(Table1[[#This Row],[Joining Date]],TODAY(),3) -> 8.4
... A505: EMP500 | B505: Meera | C505: Sharma | D505: Female | E505: 30098 | F505: 44 | G505: Finance | H505: Delhi | I505: Finance Analyst | J505: Rohan Joshi | K505: Contract | L505: On Leave | M505: 45142 | N505: 9 | O505: 75871 | P505: 17417 | Q505: 4 | R505: 90.6 | S505: 26 | T505: meera.sharma500@company.com | U505: 9996467805 | V505: Delhi | W505: Delhi | X505: India | Y505: BA | Z505: Morning | AA505: =YEARFRAC(Table1[[#This Row],[Joining Date]],TODAY(),3) -> 3.0465753
AA506: =YEARFRAC(Table1[[#This Row],[Joining Date]],TODAY(),3) -> 126.72329
AA507: =YEARFRAC(Table1[[#This Row],[Joining Date]],TODAY(),3) -> 126.72329
AA508: =YEARFRAC(Table1[[#This Row],[Joining Date]],TODAY(),3) -> 126.72329
AA509: =YEARFRAC(Table1[[#This Row],[Joining Date]],TODAY(),3) -> 126.72329
AA510: =YEARFRAC(Table1[[#This Row],[Joining Date]],TODAY(),3) -> 126.72329
AA511: =YEARFRAC(Table1[[#This Row],[Joining Date]],TODAY(),3) -> 126.72329
AA512: =YEARFRAC(Table1[[#This Row],[Joining Date]],TODAY(),3) -> 126.72329
AA513: =YEARFRAC(Table1[[#This Row],[Joining Date]],TODAY(),3) -> 126.72329
AA514: =YEARFRAC(Table1[[#This Row],[Joining Date]],TODAY(),3) -> 126.72329
AA515: =YEARFRAC(Table1[[#This Row],[Joining Date]],TODAY(),3) -> 126.72329
AA516: =YEARFRAC(Table1[[#This Row],[Joining Date]],TODAY(),3) -> 126.72329
AA517: =YEARFRAC(Table1[[#This Row],[Joining Date]],TODAY(),3) -> 126.72329
... AA968: =YEARFRAC(Table1[[#This Row],[Joining Date]],TODAY(),3) -> 126.72329
